<mujoco model="dexplay_allegro_phase0">
  <compiler angle="radian"/>
  <option timestep="0.0025" integrator="RK4" gravity="0 0 -1.5" iterations="30" ls_iterations="20"/>
  <size njmax="2000" nconmax="2000"/>

  <default>
    <joint damping="0.06" armature="0.005" limited="true"/>
    <geom condim="6" friction="1.0 0.05 0.002"/>
  </default>

  <worldbody>
    <light pos="0 0 1.2"/>
    <geom name="table" type="plane" size="1 1 0.1" rgba="0.85 0.85 0.85 1"/>

    <body name="palm" pos="0 0 0.09">
      <geom name="palm_geom" type="box" size="0.042 0.050 0.012" rgba="0.18 0.18 0.24 1" mass="0.25"/>
      <site name="palm_center" pos="0 0 0.014" size="0.004" rgba="0 1 0 1"/>

      <body name="thumb_base" pos="-0.020 -0.035 0.008">
        <joint name="thumb_0" type="hinge" axis="0 0 1" range="-0.50 0.80"/>
        <geom type="capsule" fromto="0 0 0 0.020 0.000 0.000" size="0.008" rgba="0.82 0.60 0.42 1" mass="0.03"/>
        <body pos="0.020 0.000 0.000">
          <joint name="thumb_1" type="hinge" axis="0 1 0" range="-0.30 1.20"/>
          <geom type="capsule" fromto="0 0 0 0.024 0.000 0.000" size="0.007" rgba="0.82 0.60 0.42 1" mass="0.02"/>
          <body pos="0.024 0.000 0.000">
            <joint name="thumb_2" type="hinge" axis="0 1 0" range="-0.20 1.40"/>
            <geom type="capsule" fromto="0 0 0 0.020 0.000 0.000" size="0.0065" rgba="0.82 0.60 0.42 1" mass="0.016"/>
            <body pos="0.020 0.000 0.000">
              <joint name="thumb_3" type="hinge" axis="0 1 0" range="-0.20 1.30"/>
              <geom type="capsule" fromto="0 0 0 0.018 0.000 0.000" size="0.006" rgba="0.82 0.60 0.42 1" mass="0.012"/>
            </body>
          </body>
        </body>
      </body>

      <body name="index_base" pos="0.015 -0.030 0.010">
        <joint name="index_0" type="hinge" axis="0 0 1" range="-0.40 0.40"/>
        <geom type="capsule" fromto="0 0 0 0.028 0 0" size="0.0075" rgba="0.75 0.58 0.42 1" mass="0.025"/>
        <body pos="0.028 0 0">
          <joint name="index_1" type="hinge" axis="0 1 0" range="-0.20 1.40"/>
          <geom type="capsule" fromto="0 0 0 0.023 0 0" size="0.0068" rgba="0.75 0.58 0.42 1" mass="0.019"/>
          <body pos="0.023 0 0">
            <joint name="index_2" type="hinge" axis="0 1 0" range="-0.20 1.40"/>
            <geom type="capsule" fromto="0 0 0 0.020 0 0" size="0.0062" rgba="0.75 0.58 0.42 1" mass="0.014"/>
            <body pos="0.020 0 0">
              <joint name="index_3" type="hinge" axis="0 1 0" range="-0.20 1.30"/>
              <geom type="capsule" fromto="0 0 0 0.018 0 0" size="0.0058" rgba="0.75 0.58 0.42 1" mass="0.010"/>
            </body>
          </body>
        </body>
      </body>

      <body name="middle_base" pos="0.015 0.000 0.010">
        <joint name="middle_0" type="hinge" axis="0 0 1" range="-0.40 0.40"/>
        <geom type="capsule" fromto="0 0 0 0.030 0 0" size="0.0075" rgba="0.74 0.58 0.43 1" mass="0.026"/>
        <body pos="0.030 0 0">
          <joint name="middle_1" type="hinge" axis="0 1 0" range="-0.20 1.40"/>
          <geom type="capsule" fromto="0 0 0 0.024 0 0" size="0.0068" rgba="0.74 0.58 0.43 1" mass="0.019"/>
          <body pos="0.024 0 0">
            <joint name="middle_2" type="hinge" axis="0 1 0" range="-0.20 1.40"/>
            <geom type="capsule" fromto="0 0 0 0.021 0 0" size="0.0062" rgba="0.74 0.58 0.43 1" mass="0.014"/>
            <body pos="0.021 0 0">
              <joint name="middle_3" type="hinge" axis="0 1 0" range="-0.20 1.30"/>
              <geom type="capsule" fromto="0 0 0 0.018 0 0" size="0.0058" rgba="0.74 0.58 0.43 1" mass="0.010"/>
            </body>
          </body>
        </body>
      </body>

      <body name="ring_base" pos="0.015 0.030 0.010">
        <joint name="ring_0" type="hinge" axis="0 0 1" range="-0.40 0.40"/>
        <geom type="capsule" fromto="0 0 0 0.028 0 0" size="0.0073" rgba="0.72 0.57 0.41 1" mass="0.024"/>
        <body pos="0.028 0 0">
          <joint name="ring_1" type="hinge" axis="0 1 0" range="-0.20 1.40"/>
          <geom type="capsule" fromto="0 0 0 0.022 0 0" size="0.0066" rgba="0.72 0.57 0.41 1" mass="0.018"/>
          <body pos="0.022 0 0">
            <joint name="ring_2" type="hinge" axis="0 1 0" range="-0.20 1.40"/>
            <geom type="capsule" fromto="0 0 0 0.019 0 0" size="0.0060" rgba="0.72 0.57 0.41 1" mass="0.013"/>
            <body pos="0.019 0 0">
              <joint name="ring_3" type="hinge" axis="0 1 0" range="-0.20 1.30"/>
              <geom type="capsule" fromto="0 0 0 0.017 0 0" size="0.0056" rgba="0.72 0.57 0.41 1" mass="0.009"/>
            </body>
          </body>
        </body>
      </body>
    </body>

    <body name="cube" pos="0.0 0.0 0.125">
      <freejoint name="cube_free"/>
      <geom name="cube_geom" type="box" size="0.015 0.015 0.015" mass="0.035" rgba="0.25 0.52 0.88 1"/>
    </body>
  </worldbody>

  <keyframe>
    <key name="default" qpos="0.25 0.60 0.70 0.55 0.00 0.50 0.60 0.55 0.05 0.55 0.65 0.55 0.08 0.58 0.68 0.58 0 0 0.125 1 0 0 0"/>
  </keyframe>
</mujoco>
